<mujoco model="tentacle">
  <compiler coordinate="local" inertiafromgeom="true"/>

  <option gravity="0 0 -9.81" integrator="RK4" timestep="0.005"/>

  <default>
    <joint type="hinge"  pos="0 0 0" axis="0 1 0" limited='true' damping="0.05" />
    <geom type="capsule" conaffinity="1" contype="1" condim='3'
          friction=".1 .1 .1" rgba="0 .8 .0 1" pos='0 0 0' margin="0.001"/>
    <site type="sphere" rgba="1 1 1 0.5" pos="0 0 0" size="0.0001"/>
    <motor ctrllimited='true' gear="10" />
  </default>


  <asset>
    <texture name="texplane" type="2d" builtin="checker" rgb1=".2 .9 .4" rgb2=".1 .7 .2" width="100" height="100"/>
    <material name='MatPlane' reflectance='0.0' texture="texplane" texrepeat="1 1" texuniform="true"/>
  </asset>

  <visual>
    <quality shadowsize="4096"/>
  </visual>

  <custom>
    <numeric data="0" name="frame_skip"/>
  </custom>

  <size nstack="3000"/>

  <!-- world -->
  <worldbody>
    <!-- sun -->
    <light diffuse=".5 .5 .5" pos="0 30 30" dir="0 -1 -1"/>

    <!-- ground -->
    <geom name='floor' size='10 10 0.125' type='plane' material="MatPlane"/>

    <!-- scorpion -->
    <body name="agent" pos="0 3 0">

  <!-- base -->
  <geom name='base' type='cylinder' fromto='0 0 0  0 0 .15' size='.5' rgba=".4 .4 .0 1"/>
  <geom fromto="0 0 .1 0 0 .15" size="0.1"/>

  <!-- segment 1 -->
  <body name="segment_1" pos="0 0 0.25">
    <joint name="hinge_1" range=' -70 +70'/>
    <geom fromto="0 0 0 0 0 .9" size="0.075"/>

    <!-- segment 2 -->
    <body name="segment_2" pos="0 0 .95">
      <joint name="hinge_2" range=' -120 +120'/>
      <geom fromto="0 0 0 0 0 .7" size="0.06"/>

      <!-- segment 3 -->
      <body name="segment_3" pos="0 0 .75">
        <joint name="hinge_3" range=' -150 +150'/>
        <geom fromto="0 0 0 0 0 .5" size="0.05"/>

        <!-- head -->
        <body name="head" pos="0 0 .5">
          <geom type='cylinder' fromto='0 0 0  0 0 .06' rgba="1.2 1.2 0. 1" size='.06'/>
          <site name="head" pos="0 0 0.06" rgba=".2 .2 1.5 0.5" size='.06'/>
        </body>
      </body>
    </body>
  </body>
</body>



    <!-- Target -->
    <body name="target" pos="0 3 1.5">
      <joint name="target_x" type="slide" axis="1 0 0" range="-3 +3" damping="0" frictionloss="1e10" frictional="true" />
      <joint name="target_z" type="slide" axis="0 0 1" range="-1 +1" damping="0" frictionloss="1e10" frictional="true" />

      <geom type="sphere" conaffinity="0" contype="0" rgba="1. 0. 0. 1." size=".05" mass="2e3"/>
      <site name="target" pos="0 0 0.025"/>
    </body>

  </worldbody>

  <actuator>
  <motor name="hinge_1" ctrlrange="-200 +200" joint="hinge_1"/>
  <motor name="hinge_2" ctrlrange="-150 +150" joint="hinge_2"/>
  <motor name="hinge_3" ctrlrange=" -50  +50" joint="hinge_3"/>
</actuator>


</mujoco>
