<mujoco model='world'>
  <compiler coordinate='local' inertiafromgeom='true'/>

  <option gravity='0 0 -9.81' integrator='RK4' timestep='0.005'/>

  <default>
    <joint type='hinge'  pos='0 0 0' axis='0 1 0' limited='true' damping='0.05' />
    <geom type='capsule' conaffinity='1' contype='1' condim='3'
          friction='.1 .1 .1' rgba='0 .8 .0 1' pos='0 0 0' margin='0.001'/>
    <site type='sphere' rgba='1 1 1 0.5' pos='0 0 0' size='0.0001'/>
    <motor ctrllimited='true'/>
  </default>

  <asset>
    <texture name='texplane' type='2d' builtin='checker' rgb1='.2 .9 .4' rgb2='.1 .7 .2' width='100' height='100'/>
    <material name='MatPlane' reflectance='0.0' texture='texplane' texrepeat='1 1' texuniform='true'/>
  </asset>

  <visual>
    <quality shadowsize='4096'/>
  </visual>

  <custom>
    <numeric data='0' name='frame_skip'/>
  </custom>

  <size nstack='3000'/>

  b'<worldbody>\n    <light diffuse=".6 .6 .6" pos="0 30 30" dir="0 -1 -1"></light>\n    <geom name="floor" size="20 20 0.125" type="plane" material="MatPlane"></geom>\n    b'<body name="world.scorpion" pos="0 0 0">\n    <body name="world.scorpion.cart" pos="0 0 0">\n      <geom type="box" pos="0 0 0.1" size=".5 .5 .1" rgba=".2 .2 .0 1"></geom>\n      <body name="world.scorpion.head" pos="0 0 0">\n        <joint name="world.scorpion.head_a" axis="0 0 1" range="-120 +120"></joint>\n        <geom type="cylinder" fromto="0 0 .2  0 0 0.25" size=".15" rgba="1.5 1.5 0 1"></geom>\n        b'<body name="world.scorpion.tentacle" pos="0 0 .2">\n    <geom type="box" pos="0 0 0.1" size=".3 .3 .05" rgba="0.6 0.6 0 1"></geom>\n    <geom type="sphere" pos="0 0 .1" size="0.12"></geom>\n    <body name="world.scorpion.tentacle.s1" pos="0 0 0.17">\n      <joint name="world.scorpion.tentacle.s1_a" range=" -70 +70"></joint>\n      <geom fromto="0 0 0 0 0 .9" size="0.075"></geom>\n      <body name="world.scorpion.tentacle.s2" pos="0 0 .95">\n        <joint name="world.scorpion.tentacle.s2_a" range=" -120 +120"></joint>\n        <geom fromto="0 0 0 0 0 .7" size="0.06"></geom>\n        <body name="world.scorpion.tentacle.s3" pos="0 0 .75">\n          <joint name="world.scorpion.tentacle.s3_a" range=" -150 +150"></joint>\n          <geom fromto="0 0 0 0 0 .5" size="0.05"></geom>\n          <body name="world.scorpion.tentacle.head" pos="0 0 .5">\n            <geom type="cylinder" fromto="0 0 0  0 0 .06" rgba="1.2 1.2 0. 1" size=".06"></geom>\n            <site name="world.scorpion.tentacle.site_head" pos="0 0 0.06" rgba=".2 .2 1.5 0.5" size=".06"></site>\n          </body>\n        </body>\n      </body>\n    </body>\n  </body>\n\n  '\n        b'<body name="world.scorpion.target" pos="0 0 0">\n    <site name="world.scorpion.target.surface" type="box" size="2 0.01 1.5" pos="0 0 1.5" rgba="1 1 0 .1"></site>\n    <body name="world.scorpion.target.coords" pos="0 0 1.5">\n      <joint name="world.scorpion.target.coords_x" type="slide" axis="1 0 0" range="-2.0 +2.0"></joint>\n      <joint name="world.scorpion.target.coords_z" type="slide" axis="0 0 1" range="-1.0 +1.5"></joint>\n      <geom type="sphere" conaffinity="0" contype="0" rgba="0. 0. 0. 0." size=".05" mass="1e-3"></geom>\n      <site name="world.scorpion.target.site_center" pos="0 0 0" size="0.05" rgba="1.5 1.5 0. 0.9"></site>\n    </body>\n  </body>\n\n  '\n      </body>\n    </body>\n  </body>\n\n  '\n    b'<body name="world.ball" pos="0 0 5">\n    <joint name="world.ball.coords_x" type="slide" axis="1 0 0" range="-100.0 +100.0"></joint>\n    <joint name="world.ball.coords_y" type="slide" axis="0 1 0" range="-100.0 +100.0"></joint>\n    <joint name="world.ball.coords_z" type="slide" axis="0 0 1" range="-100.0 +100.0"></joint>\n    <geom type="sphere" conaffinity="1" contype="1" rgba="0.05 1. 3. .4" size=".2" mass="3e-1"></geom>\n    <site name="world.ball" pos="0 0 -.2" size=".001" rgba="0 0 0 0"></site>\n  </body>\n\n  '\n  </worldbody>\n'
  <sensor>
    
b'<jointpos name="world.scorpion.sensor_head_pos" joint="world.scorpion.head_a"></jointpos>\n    'b'<jointvel name="world.scorpion.sensor_head_vel" joint="world.scorpion.head_a"></jointvel>\n  '
b'<jointpos name="world.scorpion.tentacle.sensor_s1_pos" joint="world.scorpion.tentacle.s1_a"></jointpos>\n    'b'<jointvel name="world.scorpion.tentacle.sensor_s1_vel" joint="world.scorpion.tentacle.s1_a"></jointvel>\n    'b'<jointpos name="world.scorpion.tentacle.sensor_s2_pos" joint="world.scorpion.tentacle.s2_a"></jointpos>\n    'b'<jointvel name="world.scorpion.tentacle.sensor_s2_vel" joint="world.scorpion.tentacle.s2_a"></jointvel>\n    'b'<jointpos name="world.scorpion.tentacle.sensor_s3_pos" joint="world.scorpion.tentacle.s3_a"></jointpos>\n    'b'<jointvel name="world.scorpion.tentacle.sensor_s3_vel" joint="world.scorpion.tentacle.s3_a"></jointvel>\n  '
b'<jointpos name="world.scorpion.target.sensor_x" joint="world.scorpion.target.coords_x"></jointpos>\n    'b'<jointpos name="world.scorpion.target.sensor_z" joint="world.scorpion.target.coords_z"></jointpos>\n  '
b'<jointpos name="world.ball.sensor_x" joint="world.ball.coords_x"></jointpos>\n    'b'<jointpos name="world.ball.sensor_y" joint="world.ball.coords_y"></jointpos>\n    'b'<jointpos name="world.ball.sensor_z" joint="world.ball.coords_z"></jointpos>\n    'b'<jointvel name="world.ball.sensor_vx" joint="world.ball.coords_x"></jointvel>\n    'b'<jointvel name="world.ball.sensor_vy" joint="world.ball.coords_y"></jointvel>\n    'b'<jointvel name="world.ball.sensor_vz" joint="world.ball.coords_z"></jointvel>\n    'b'<accelerometer name="world.ball.sensor_accelerometer" site="world.ball"></accelerometer>\n  '
  </sensor>
  <actuator>
    
b'<motor name="world.scorpion.actuator_head" ctrlrange="-10 +10" joint="world.scorpion.head_a"></motor>\n    'b'<position name="world.scorpion.actuator_target_x" ctrlrange="-2 +2" kp="1" joint="world.scorpion.target.coords_x"></position>\n    'b'<position name="world.scorpion.actuator_target_z" ctrlrange="-1 +2" kp="1" joint="world.scorpion.target.coords_z"></position>\n  '
b'<motor name="world.scorpion.tentacle.actuator_s1" ctrlrange="-2000 +2000" joint="world.scorpion.tentacle.s1_a"></motor>\n    'b'<motor name="world.scorpion.tentacle.actuator_s2" ctrlrange="-1500 +1500" joint="world.scorpion.tentacle.s2_a"></motor>\n    'b'<motor name="world.scorpion.tentacle.actuator_s3" ctrlrange=" -500  +500" joint="world.scorpion.tentacle.s3_a"></motor>\n  '


  </actuator>

</mujoco>
